---
type: 'Post'
date: 2020-05-28
title: Go - Error
tags: [go]
description: Go 的错误处理主要基于两个概念：错误类型和错误值。
---

Go 是一种编程语言，它提供了一种简单而有效的错误处理机制。 Go 的错误处理主要基于两个概念：错误类型和错误值。

在 Go 中，错误类型是一个接口类型，定义了一个名为 `error` 的预定义接口。该接口只有一个方法 `Error()`，它返回一个字符串，表示错误的描述信息。任何实现了 `error` 接口的类型都可以被视为一个错误类型。

错误值则是实现了 `error` 接口的具体实例。当出现错误时，通常会返回一个错误值来表示错误的发生。在函数调用中，通常会将错误作为函数的最后一个返回值返回。如果没有错误发生，错误值为 `nil`。

下面是一个简单的示例，展示了如何在 Go 中处理错误：

```go
package main

import (
	"errors"
	"fmt"
)

func divide(x, y int) (int, error) {
	if y == 0 {
		return 0, errors.New("division by zero")
	}
	return x / y, nil
}

func main() {
	result, err := divide(10, 2)
	if err != nil {
		fmt.Println("Error:", err)
	} else {
		fmt.Println("Result:", result)
	}
}
```

在上面的示例中，`divide` 函数用于执行整数除法运算。如果除数为零，则返回一个错误值，表示发生了除以零的错误。在 `main` 函数中，我们调用 `divide` 函数，并使用错误值进行错误检查。如果错误值不为 `nil`，则打印错误信息；否则，打印计算结果。

Go 还提供了一种更简便的错误处理方式，即使用 `errors` 包中的 `Errorf` 函数。该函数类似于 `fmt.Printf`，可以通过格式化字符串和参数创建一个新的错误值。例如：

```go
return nil, fmt.Errorf("error occurred: %v", someValue)
```

这样可以更方便地生成自定义的错误信息。

此外，Go 还支持自定义错误类型。开发人员可以通过定义满足 `error` 接口的自定义类型来表示特定的错误。这样可以提供更丰富的错误信息和错误处理逻辑。

Go 的错误处理机制基于错误类型和错误值。通过返回错误值，并使用条件语句进行错误检查，开发人员可以有效地处理和传播错误信息。

除了使用错误值进行错误检查外，Go 还提供了另外两种错误处理方式：错误恢复（Error Recovery）和错误日志记录（Error Logging）。

## 错误恢复

在某些情况下，当程序遇到错误时，我们可能希望程序能够继续执行而不是立即终止。为了实现这种错误恢复的能力，Go 提供了 recover 函数和 panic 机制。panic 用于引发一个错误，并立即停止当前函数的执行，然后程序会开始回溯执行调用栈，直到遇到包含 recover 函数的延迟函数调用。recover 用于捕获 panic 引发的错误，并允许程序进行一些处理。通过使用 defer 关键字和 recover 函数，我们可以在一些关键的代码段中设置恢复机制，以确保程序在遇到错误时能够继续执行，并进行一些必要的清理操作。

```go
func process() {
	defer func() {
		if err := recover(); err != nil {
			fmt.Println("Recovered from error:", err)
		}
	}()

	// 执行可能引发错误的代码
	// 当遇到错误时，使用 panic 引发错误
	panic("something went wrong")
}
```

process 函数中的 panic 语句会引发一个错误，并立即停止函数的执行。但由于设置了延迟函数调用和 recover 函数，程序会继续执行 defer 块中的代码，捕获错误并进行处理。

## 错误日志记录

除了简单地检查错误和恢复错误外，有时我们还需要记录错误信息以进行故障排查和日志记录。在 Go 中，通常使用标准库中的 log 包或第三方日志库（如 logrus、zap 等）来记录错误日志。这些库提供了各种级别的日志记录功能，可以将错误信息和其他相关信息写入日志文件或其他输出目标。

```go
package main

import (
	"errors"
	"log"
)

func main() {
	err := someFunction()
	if err != nil {
		log.Println("Error:", err)
	}
}

func someFunction() error {
	return errors.New("something went wrong")
}
```

使用标准库中的 log 包将错误信息记录到日志中。可以使用不同的日志级别（如 Println、Printf、Error 等）根据需要进行日志记录。

如果在错误恢复机制中没有设置延迟函数调用和 recover 函数，那么在 panic 引发错误后，程序将会立即终止并打印出错误信息。这种情况下，错误将无法被捕获和处理，程序会退出。

例如，考虑以下代码：

```go
func process() {
	// 执行可能引发错误的代码
	// 当遇到错误时，使用 panic 引发错误
	panic("something went wrong")
}

func main() {
	process()
	fmt.Println("After process")
}
```

在上述示例中，当 process 函数执行到 panic 语句时，程序会立即终止，并输出以下错误信息：

```shell
panic: something went wrong

goroutine 1 [running]:
main.process()
	/Users/user/main.go:5 +0x39
main.main()
	/Users/user/main.go:10 +0x20
exit status 2
```

可以看到，错误信息指示发生了 panic，并显示了调用栈的信息。然后，程序会退出，并不会继续执行 fmt.Println("After process") 这行代码。

因此，在错误恢复机制中，如果没有设置延迟函数调用和 recover 函数，panic 引发的错误将会导致程序的立即终止。为了能够恢复错误并继续执行程序，必须使用 defer 关键字和 recover 函数来捕获和处理错误。
